scripts/test.out
Engine stdout: S 1 AAPL 3250 4 55506410239809
Engine stdout: S 2 AAPL 3260 25 55506410387862
Engine stdout: E 1 3 1 3250 4 55506410412583
Engine stdout: S 13 AAPL 3250 4 55506410453428
Engine stdout: E 13 3 1 3250 4 55506410553727
Engine stdout: E 2 3 1 3260 21 55506410584611
Engine stdout: S 14 AAPL 3260 25 55506410616920
Engine stdout: S 4 MSFT 3250 4 55506410621039
Engine stdout: S 7 AAPL 3250 4 55506410683893
Engine stdout: E 7 15 1 3250 4 55506410728760
Engine stdout: S 8 AAPL 3260 25 55506410753923
Engine stdout: E 2 15 2 3260 4 55506410778545
Engine stdout: E 14 15 1 3260 21 55506410828576
Engine stdout: S 5 MSFT 3260 25 55506410784301
Engine stdout: S 16 MSFT 3250 4 55506410889403
Engine stdout: S 17 MSFT 3260 25 55506410931815
Engine stdout: S 19 AAPL 3250 4 55506410875622
Engine stdout: E 4 18 1 3250 4 55506410957599
Engine stdout: E 19 9 1 3250 4 55506410994455
Engine stdout: E 14 9 2 3260 4 55506411036635
Engine stdout: E 8 9 1 3260 21 55506411041475
Engine stdout: E 16 18 1 3250 4 55506411017276
Engine stdout: S 10 MSFT 3250 4 55506411088582
Engine stdout: S 11 MSFT 3260 25 55506411109832
Engine stdout: S 49 AAPL 3250 4 55506411068461
Engine stdout: E 10 18 1 3250 4 55506411130837
Engine stdout: E 5 18 1 3260 17 55506411163955
Engine stdout: E 5 12 2 3260 8 55506411181082
Engine stdout: E 17 12 1 3260 21 55506411185920
Engine stdout: S 31 AAPL 3250 4 55506411168392
Engine stdout: E 17 6 2 3260 4 55506411252572
Engine stdout: E 11 6 1 3260 25 55506411272397
Engine stdout: S 37 AAPL 3250 4 55506411245556
Engine stdout: S 43 AAPL 3250 4 55506411330085
Engine stdout: S 91 AAPL 3250 4 55506411402797
Engine stdout: S 92 AAPL 3260 25 55506411535557
Engine stdout: S 73 AAPL 3250 4 55506411571440
Engine stdout: E 49 93 1 3250 4 55506411658882
Engine stdout: S 25 AAPL 3250 4 55506411686587
Engine stdout: E 31 93 1 3250 4 55506411742789
Engine stdout: E 37 93 1 3250 4 55506411762353
Engine stdout: S 26 AAPL 3260 25 55506411781773
Engine stdout: S 115 AAPL 3250 4 55506411807890
Engine stdout: E 43 93 1 3250 4 55506411895229
Engine stdout: S 67 AAPL 3250 4 55506411924646
Engine stdout: S 32 AAPL 3260 25 55506411966833
Engine stdout: E 91 93 1 3250 4 55506411991749
Engine stdout: E 73 93 1 3250 4 55506412023117
Engine stdout: E 25 93 1 3250 4 55506412045510
Engine stdout: E 115 93 1 3250 1 55506412067799
Engine stdout: S 94 MSFT 3250 4 55506412111758
Engine stdout: S 95 MSFT 3260 25 55506412136424
Engine stdout: S 85 AAPL 3250 4 55506412092827
Engine stdout: E 94 96 1 3250 4 55506412187906
Engine stdout: E 115 27 2 3250 3 55506412218425
Engine stdout: E 95 96 1 3260 25 55506412232040
Engine stdout: E 67 27 1 3250 4 55506412256845
Engine stdout: E 85 27 1 3250 4 55506412285138
Engine stdout: E 8 27 2 3260 4 55506412307973
Engine stdout: E 92 27 1 3260 14 55506412316597
Engine stdout: S 86 AAPL 3260 25 55506412333205
Engine stdout: S 28 MSFT 3250 4 55506412339187
Engine stdout: E 92 33 2 3260 11 55506412371566
Engine stdout: S 29 MSFT 3260 25 55506412372384
Engine stdout: E 26 33 1 3260 18 55506412410838
Engine stdout: E 28 30 1 3250 4 55506412417565
Engine stdout: E 29 30 1 3260 25 55506412448689
Engine stdout: S 44 AAPL 3260 25 55506412446674
Engine stdout: S 34 MSFT 3250 4 55506412479805
Engine stdout: E 26 87 2 3260 7 55506412511497
Engine stdout: S 35 MSFT 3260 25 55506412530381
Engine stdout: E 34 36 1 3250 4 55506412554983
Engine stdout: S 61 AAPL 3250 4 55506412530150
Engine stdout: E 35 36 1 3260 25 55506412571268
Engine stdout: E 61 87 1 3250 4 55506412606349
Engine stdout: E 32 87 1 3260 18 55506412631930
Engine stdout: S 20 AAPL 3260 25 55506412663791
Engine stdout: S 88 MSFT 3250 4 55506412677035
Engine stdout: E 32 45 2 3260 7 55506412711598
Engine stdout: S 89 MSFT 3260 25 55506412726481
Engine stdout: E 86 45 1 3260 22 55506412739716
Engine stdout: E 88 90 1 3250 4 55506412764454
Engine stdout: S 46 MSFT 3250 4 55506412804834
Engine stdout: S 47 MSFT 3260 25 55506412831462
Engine stdout: S 133 AAPL 3250 4 55506412792874
Engine stdout: E 46 90 1 3250 4 55506412855920
Engine stdout: E 89 90 1 3260 21 55506412934973
Engine stdout: S 134 AAPL 3260 25 55506412896792
Engine stdout: E 89 48 2 3260 4 55506412979185
Engine stdout: E 47 48 1 3260 25 55506412989761
Engine stdout: E 133 21 1 3250 4 55506412994608
Engine stdout: E 86 21 2 3260 3 55506413026644
Engine stdout: E 44 21 1 3260 22 55506413045547
Engine stdout: S 22 MSFT 3250 4 55506413079889
Engine stdout: S 23 MSFT 3260 25 55506413094818
Engine stdout: S 55 AAPL 3250 4 55506413063050
Engine stdout: E 22 24 1 3250 4 55506413122952
Engine stdout: E 23 24 1 3260 25 55506413169518
Engine stdout: S 50 AAPL 3260 25 55506413177801
Engine stdout: S 116 AAPL 3260 25 55506413231432
Engine stdout: E 55 135 1 3250 4 55506413272108
Engine stdout: E 44 135 2 3260 3 55506413329934
Engine stdout: E 20 135 1 3260 22 55506413358955
Engine stdout: S 136 MSFT 3250 4 55506413395489
Engine stdout: S 137 MSFT 3260 25 55506413412983
Engine stdout: E 136 138 1 3250 4 55506413426900
Engine stdout: E 137 138 1 3260 25 55506413434644
Engine stdout: S 97 AAPL 3250 4 55506413369966
Engine stdout: S 68 AAPL 3260 25 55506413480739
Engine stdout: E 97 51 1 3250 4 55506413527231
Engine stdout: E 20 51 2 3260 3 55506413547584
Engine stdout: S 79 AAPL 3250 4 55506413556169
Engine stdout: E 79 51 1 3250 4 55506413634209
Engine stdout: E 134 51 1 3260 18 55506413657278
Engine stdout: S 80 AAPL 3260 25 55506413669095
Engine stdout: S 52 MSFT 3250 4 55506413688312
Engine stdout: E 134 117 2 3260 7 55506413691709
Engine stdout: S 53 MSFT 3260 25 55506413740555
Engine stdout: E 50 117 1 3260 22 55506413781113
Engine stdout: E 52 54 1 3250 4 55506413794719
Engine stdout: E 53 54 1 3260 25 55506413828873
Engine stdout: S 118 MSFT 3250 4 55506413841329
Engine stdout: S 119 MSFT 3260 25 55506413869500
Engine stdout: E 118 120 1 3250 4 55506413893763
Engine stdout: S 121 AAPL 3250 4 55506413821186
Engine stdout: E 119 120 1 3260 25 55506413909135
Engine stdout: E 121 69 1 3250 4 55506413944579
Engine stdout: S 122 AAPL 3260 25 55506413974924
Engine stdout: E 50 69 2 3260 3 55506414004123
Engine stdout: E 116 69 1 3260 22 55506414009408
Engine stdout: E 116 81 2 3260 3 55506414037475
Engine stdout: E 68 81 1 3260 25 55506414048549
Engine stdout: E 80 81 1 3260 1 55506414052707
Engine stdout: S 38 AAPL 3260 25 55506414088948
Engine stdout: E 80 39 2 3260 24 55506414106959
Engine stdout: S 139 AAPL 3250 4 55506414111238
Engine stdout: E 139 39 1 3250 4 55506414155116
Engine stdout: E 122 39 1 3260 1 55506414169131
Engine stdout: S 140 AAPL 3260 25 55506414173181
Engine stdout: E 122 141 2 3260 24 55506414196184
Engine stdout: E 38 141 1 3260 5 55506414206436
Engine stdout: E 38 123 2 3260 20 55506414226633
Engine stdout: E 140 123 1 3260 9 55506414233739
Engine stdout: S 70 MSFT 3250 4 55506414229442
Engine stdout: S 103 AAPL 3250 4 55506414279274
Engine stdout: S 71 MSFT 3260 25 55506414314232
Engine stdout: S 145 AAPL 3250 4 55506414328480
Engine stdout: S 40 MSFT 3250 4 55506414341873
Engine stdout: S 146 AAPL 3260 25 55506414385775
Engine stdout: S 41 MSFT 3260 25 55506414389487
Engine stdout: S 151 AAPL 3250 4 55506414426609
Engine stdout: S 124 MSFT 3250 4 55506414432632
Engine stdout: E 103 147 1 3250 4 55506414492598
Engine stdout: E 70 72 1 3250 4 55506414494863
Engine stdout: E 145 147 1 3250 4 55506414524888
Engine stdout: E 40 72 1 3250 4 55506414566794
Engine stdout: E 151 147 1 3250 4 55506414584962
Engine stdout: E 140 147 2 3260 16 55506414631610
Engine stdout: E 146 147 1 3260 1 55506414648627
Engine stdout: E 124 72 1 3250 4 55506414615411
Engine stdout: S 74 AAPL 3260 25 55506414672409
Engine stdout: E 71 72 1 3260 17 55506414694810
Engine stdout: E 146 75 2 3260 24 55506414730915
Engine stdout: S 82 MSFT 3250 4 55506414741750
Engine stdout: E 82 42 1 3250 4 55506414769066
Engine stdout: E 71 42 2 3260 8 55506414774068
Engine stdout: E 41 42 1 3260 17 55506414777566
Engine stdout: E 74 75 1 3260 5 55506414783970
Engine stdout: S 142 MSFT 3250 4 55506414783346
